<?xml version="1.0" ?>
<!-- =================================================================================== -->
<!-- |    This document was autogenerated by xacro from small_arm.urdf.xacro           | -->
<!-- |    EDITING THIS FILE BY HAND IS NOT RECOMMENDED                                 | -->
<!-- =================================================================================== -->
<robot name="small_arm">
  <material name="silver">
    <color rgba="0.700 0.700 0.700 1.000"/>
  </material>
  <!-- <xacro:include filename="$(find SMW-G02_urdf_description)/urdf/SMW-G02_urdf.trans" />
  <xacro:include filename="$(find SMW-G02_urdf_description)/urdf/SMW-G02_urdf.gazebo" /> -->
  <link name="world"/>
  <joint name="origin_to_base_link" type="fixed">
    <origin rpy="0 0 0" xyz="0 0 0"/>
    <parent link="world"/>
    <child link="base_link"/>
    <axis xyz="0 0 0"/>
  </joint>
  <link name="base_link">
    <inertial>
      <origin rpy="0 0 0" xyz="-0.0002999964758485541 -0.01002821324623266 0.02805569132780727"/>
      <mass value="1.29137439344346"/>
      <inertia ixx="0.001017" ixy="-0.0" ixz="0.0" iyy="0.000798" iyz="-3.2e-05" izz="0.00122"/>
    </inertial>
    <visual>
      <origin rpy="0 0 0" xyz="0 0 0"/>
      <geometry>
        <mesh filename="/home/taiting/docker_ws/timda_dual_arm_ws/src/tb4_arm_ros2/small_arm_description/meshes/base_link.stl" scale="0.001 0.001 0.001"/>
      </geometry>
      <material name="silver"/>
    </visual>
    <collision>
      <origin rpy="0 0 0" xyz="0 0 0"/>
      <geometry>
        <mesh filename="/home/taiting/docker_ws/timda_dual_arm_ws/src/tb4_arm_ros2/small_arm_description/meshes/base_link.stl" scale="0.001 0.001 0.001"/>
      </geometry>
    </collision>
  </link>
  <link name="link1">
    <inertial>
      <origin rpy="0 0 0" xyz="0.0005539067623238434 -2.1382866212631147e-05 0.03707065153568121"/>
      <mass value="0.8171892676957183"/>
      <inertia ixx="0.000382" ixy="0.0" ixz="-3e-06" iyy="0.000408" iyz="0.0" izz="0.00022"/>
    </inertial>
    <visual>
      <origin rpy="0 0 0" xyz="0.0003 -4.1e-05 -0.053"/>
      <geometry>
        <mesh filename="/home/taiting/docker_ws/timda_dual_arm_ws/src/tb4_arm_ros2/small_arm_description/meshes/link_1_1.stl" scale="0.001 0.001 0.001"/>
      </geometry>
      <material name="silver"/>
    </visual>
    <collision>
      <origin rpy="0 0 0" xyz="0.0003 -4.1e-05 -0.053"/>
      <geometry>
        <mesh filename="/home/taiting/docker_ws/timda_dual_arm_ws/src/tb4_arm_ros2/small_arm_description/meshes/link_1_1.stl" scale="0.001 0.001 0.001"/>
      </geometry>
    </collision>
  </link>
  <link name="link2">
    <inertial>
      <origin rpy="0 0 0" xyz="-0.024402873741152922 -0.0009180927250929553 0.08726652583609527"/>
      <mass value="2.211704028669612"/>
      <inertia ixx="0.005529" ixy="-0.0" ixz="-2.5e-05" iyy="0.005935" iyz="8.6e-05" izz="0.001201"/>
    </inertial>
    <visual>
      <origin rpy="0 0 0" xyz="-0.0242 0.0 -0.109"/>
      <geometry>
        <mesh filename="/home/taiting/docker_ws/timda_dual_arm_ws/src/tb4_arm_ros2/small_arm_description/meshes/link_2_1.stl" scale="0.001 0.001 0.001"/>
      </geometry>
      <material name="silver"/>
    </visual>
    <collision>
      <origin rpy="0 0 0" xyz="-0.0242 0.0 -0.109"/>
      <geometry>
        <mesh filename="/home/taiting/docker_ws/timda_dual_arm_ws/src/tb4_arm_ros2/small_arm_description/meshes/link_2_1.stl" scale="0.001 0.001 0.001"/>
      </geometry>
    </collision>
  </link>
  <link name="link3">
    <inertial>
      <origin rpy="0 0 0" xyz="-0.024562745448922518 0.06329760185292234 0.004043498969020454"/>
      <mass value="1.4560374497113304"/>
      <inertia ixx="0.001645" ixy="2e-06" ixz="-0.0" iyy="0.001003" iyz="-1.2e-05" izz="0.001935"/>
    </inertial>
    <visual>
      <origin rpy="0 0 0" xyz="-0.0241 -0.0 -0.264"/>
      <geometry>
        <mesh filename="/home/taiting/docker_ws/timda_dual_arm_ws/src/tb4_arm_ros2/small_arm_description/meshes/link_3_1.stl" scale="0.001 0.001 0.001"/>
      </geometry>
      <material name="silver"/>
    </visual>
    <collision>
      <origin rpy="0 0 0" xyz="-0.0241 -0.0 -0.264"/>
      <geometry>
        <mesh filename="/home/taiting/docker_ws/timda_dual_arm_ws/src/tb4_arm_ros2/small_arm_description/meshes/link_3_1.stl" scale="0.001 0.001 0.001"/>
      </geometry>
    </collision>
  </link>
  <link name="link4">
    <inertial>
      <origin rpy="0 0 0" xyz="-0.0001915907936059267 0.028749765366266278 1.3933167071766839e-05"/>
      <mass value="0.4445934457308041"/>
      <inertia ixx="0.000143" ixy="1e-06" ixz="-0.0" iyy="8.2e-05" iyz="-0.0" izz="0.00014"/>
    </inertial>
    <visual>
      <origin rpy="0 0 0" xyz="0.0006 -0.100766 -0.265316"/>
      <geometry>
        <mesh filename="/home/taiting/docker_ws/timda_dual_arm_ws/src/tb4_arm_ros2/small_arm_description/meshes/link_4_1.stl" scale="0.001 0.001 0.001"/>
      </geometry>
      <material name="silver"/>
    </visual>
    <collision>
      <origin rpy="0 0 0" xyz="0.0006 -0.100766 -0.265316"/>
      <geometry>
        <mesh filename="/home/taiting/docker_ws/timda_dual_arm_ws/src/tb4_arm_ros2/small_arm_description/meshes/link_4_1.stl" scale="0.001 0.001 0.001"/>
      </geometry>
    </collision>
  </link>
  <link name="link5">
    <inertial>
      <origin rpy="0 0 0" xyz="-0.019004907946417172 0.007238676029536678 -0.043336314243680424"/>
      <mass value="0.970501435691462"/>
      <inertia ixx="0.00064" ixy="-1e-06" ixz="-0.0" iyy="0.000557" iyz="-1.4e-05" izz="0.000514"/>
    </inertial>
    <visual>
      <origin rpy="0 0 0" xyz="-0.0174 -0.144647 -0.265316"/>
      <geometry>
        <mesh filename="/home/taiting/docker_ws/timda_dual_arm_ws/src/tb4_arm_ros2/small_arm_description/meshes/link_5_1.stl" scale="0.001 0.001 0.001"/>
      </geometry>
      <material name="silver"/>
    </visual>
    <collision>
      <origin rpy="0 0 0" xyz="-0.0174 -0.144647 -0.265316"/>
      <geometry>
        <mesh filename="/home/taiting/docker_ws/timda_dual_arm_ws/src/tb4_arm_ros2/small_arm_description/meshes/link_5_1.stl" scale="0.001 0.001 0.001"/>
      </geometry>
    </collision>
  </link>
  <link name="link6">
    <inertial>
      <origin rpy="0 0 0" xyz="-5.506012312750386e-15 4.949917709884399e-07 -0.0026212148467256724"/>
      <mass value="0.025512046719187297"/>
      <inertia ixx="2e-06" ixy="0.0" ixz="-0.0" iyy="2e-06" iyz="0.0" izz="4e-06"/>
    </inertial>
    <visual>
      <origin rpy="0 0 0" xyz="0.0016 -0.144647 -0.196297"/>
      <geometry>
        <mesh filename="/home/taiting/docker_ws/timda_dual_arm_ws/src/tb4_arm_ros2/small_arm_description/meshes/link_6_1.stl" scale="0.001 0.001 0.001"/>
      </geometry>
      <material name="silver"/>
    </visual>
    <collision>
      <origin rpy="0 0 0" xyz="0.0016 -0.144647 -0.196297"/>
      <geometry>
        <mesh filename="/home/taiting/docker_ws/timda_dual_arm_ws/src/tb4_arm_ros2/small_arm_description/meshes/link_6_1.stl" scale="0.001 0.001 0.001"/>
      </geometry>
    </collision>
  </link>
  <link name="gripper_link1">
    <inertial>
      <origin rpy="0 0 0" xyz="0.009922614801186412 -0.01909950500842314 -0.024668286066997724"/>
      <mass value="0.16533614239781452"/>
      <inertia ixx="0.000142" ixy="-0.0" ixz="5e-06" iyy="7.7e-05" iyz="-0.0" izz="8.2e-05"/>
    </inertial>
    <visual>
      <origin rpy="0 0 0" xyz="-0.0204 -0.163647 -0.169647"/>
      <geometry>
        <mesh filename="/home/taiting/docker_ws/timda_dual_arm_ws/src/tb4_arm_ros2/small_arm_description/meshes/Craw_2_1.stl" scale="0.001 0.001 0.001"/>
      </geometry>
      <material name="silver"/>
    </visual>
    <collision>
      <origin rpy="0 0 0" xyz="-0.0204 -0.163647 -0.169647"/>
      <geometry>
        <mesh filename="/home/taiting/docker_ws/timda_dual_arm_ws/src/tb4_arm_ros2/small_arm_description/meshes/Craw_2_1.stl" scale="0.001 0.001 0.001"/>
      </geometry>
    </collision>
  </link>
  <link name="gripper_link2">
    <inertial>
      <origin rpy="0 0 0" xyz="-0.004639846314339198 0.0002472053469017299 -0.02547670727420101"/>
      <mass value="0.6910133017831432"/>
      <inertia ixx="0.000328" ixy="-3e-06" ixz="-0.000126" iyy="0.000563" iyz="-1e-06" izz="0.000489"/>
    </inertial>
    <visual>
      <origin rpy="0 0 0" xyz="0.0016 -0.144647 -0.190797"/>
      <geometry>
        <mesh filename="/home/taiting/docker_ws/timda_dual_arm_ws/src/tb4_arm_ros2/small_arm_description/meshes/Craw_1_1.stl" scale="0.001 0.001 0.001"/>
      </geometry>
      <material name="silver"/>
    </visual>
    <collision>
      <origin rpy="0 0 0" xyz="0.0016 -0.144647 -0.190797"/>
      <geometry>
        <mesh filename="/home/taiting/docker_ws/timda_dual_arm_ws/src/tb4_arm_ros2/small_arm_description/meshes/Craw_1_1.stl" scale="0.001 0.001 0.001"/>
      </geometry>
    </collision>
  </link>
  <link name="camera_link">
    <inertial>
      <origin rpy="0 0 0" xyz="-0.02250186173818042 -4.850013210841442e-05 -0.012169837419761076"/>
      <mass value="0.3783798760930688"/>
      <inertia ixx="3.5e-05" ixy="-0.0" ixz="0.0" iyy="0.00024" iyz="-0.0" izz="0.000238"/>
    </inertial>
    <visual>
      <origin rpy="0 0 0" xyz="-0.0209 -0.194439 -0.219247"/>
      <geometry>
        <mesh filename="/home/taiting/docker_ws/timda_dual_arm_ws/src/tb4_arm_ros2/small_arm_description/meshes/RealSence_1.stl" scale="0.001 0.001 0.001"/>
      </geometry>
      <material name="silver"/>
    </visual>
    <collision>
      <origin rpy="0 0 0" xyz="-0.0209 -0.194439 -0.219247"/>
      <geometry>
        <mesh filename="/home/taiting/docker_ws/timda_dual_arm_ws/src/tb4_arm_ros2/small_arm_description/meshes/RealSence_1.stl" scale="0.001 0.001 0.001"/>
      </geometry>
    </collision>
  </link>
  <joint name="joint1" type="revolute">
    <origin rpy="0 0 0" xyz="-0.0003 4.1e-05 0.053"/>
    <parent link="base_link"/>
    <child link="link1"/>
    <axis xyz="-0.0 -0.0 1.0"/>
    <limit effort="1" lower="-3.14" upper="3.14" velocity="4.8"/>
  </joint>
  <joint name="joint2" type="revolute">
    <origin rpy="0 0 0" xyz="0.0245 -4.1e-05 0.056"/>
    <parent link="link1"/>
    <child link="link2"/>
    <axis xyz="1.0 -0.0 0.0"/>
    <limit effort="1" lower="-3.14" upper="3.14" velocity="4.8"/>
  </joint>
  <joint name="joint3" type="revolute">
    <origin rpy="0 0 0" xyz="-0.0001 0.0 0.155"/>
    <parent link="link2"/>
    <child link="link3"/>
    <axis xyz="1.0 0.0 0.0"/>
    <limit effort="1" lower="-3.14" upper="3.14" velocity="4.8"/>
  </joint>
  <joint name="joint4" type="revolute">
    <origin rpy="0 0 0" xyz="-0.0247 0.100766 0.001316"/>
    <parent link="link3"/>
    <child link="link4"/>
    <axis xyz="-0.0 -1.0 -0.0"/>
    <limit effort="1" lower="-3.14" upper="3.14" velocity="4.8"/>
  </joint>
  <joint name="joint5" type="revolute">
    <origin rpy="0 0 0" xyz="0.018 0.043881 0.0"/>
    <parent link="link4"/>
    <child link="link5"/>
    <axis xyz="1.0 0.0 -0.0"/>
    <limit effort="1" lower="-3.14" upper="3.14" velocity="4.8"/>
  </joint>
  <joint name="joint6" type="revolute">
    <origin rpy="0 0 0" xyz="-0.019 0.0 -0.069019"/>
    <parent link="link5"/>
    <child link="link6"/>
    <axis xyz="0.0 -0.0 -1.0"/>
    <limit effort="1" lower="-3.14" upper="3.14" velocity="4.8"/>
  </joint>
  <joint name="joint7" type="revolute">
    <origin rpy="0 0 0" xyz="0.022 0.019 -0.02115"/>
    <parent link="gripper_link2"/>
    <child link="gripper_link1"/>
    <axis xyz="0.0 1.0 0.0"/>
    <limit effort="1" lower="-3.14" upper="3.14" velocity="4.8"/>
  </joint>
  <joint name="girpper_fixed" type="fixed">
    <origin rpy="0 0 0" xyz="0.0 0.0 -0.0055"/>
    <parent link="link6"/>
    <child link="gripper_link2"/>
  </joint>
  <joint name="camera_fixed" type="fixed">
    <origin rpy="0 0 0" xyz="0.0035 0.049792 -0.046069"/>
    <parent link="link5"/>
    <child link="camera_link"/>
  </joint>
  <ros2_control name="small_arm_ros2_control" type="system">
    <hardware>
      <plugin>dynamixel_hardware/DynamixelHardware</plugin>
      <param name="usb_port">/dev/ttyUSB0</param>
      <param name="baud_rate">115200</param>
      <param name="use_dummy">false</param>
    </hardware>
    <joint name="joint1">
      <param name="id">1</param>
      <command_interface name="position"/>
      <command_interface name="velocity"/>
      <state_interface name="position"/>
      <state_interface name="velocity"/>
      <state_interface name="effort"/>
    </joint>
    <joint name="joint2">
      <param name="id">2</param>
      <command_interface name="position"/>
      <command_interface name="velocity"/>
      <state_interface name="position"/>
      <state_interface name="velocity"/>
      <state_interface name="effort"/>
    </joint>
    <joint name="joint3">
      <param name="id">3</param>
      <command_interface name="position"/>
      <command_interface name="velocity"/>
      <state_interface name="position"/>
      <state_interface name="velocity"/>
      <state_interface name="effort"/>
    </joint>
    <joint name="joint4">
      <param name="id">4</param>
      <command_interface name="position"/>
      <command_interface name="velocity"/>
      <state_interface name="position"/>
      <state_interface name="velocity"/>
      <state_interface name="effort"/>
    </joint>
    <joint name="joint5">
      <param name="id">5</param>
      <command_interface name="position"/>
      <command_interface name="velocity"/>
      <state_interface name="position"/>
      <state_interface name="velocity"/>
      <state_interface name="effort"/>
    </joint>
    <joint name="joint6">
      <param name="id">6</param>
      <command_interface name="position"/>
      <command_interface name="velocity"/>
      <state_interface name="position"/>
      <state_interface name="velocity"/>
      <state_interface name="effort"/>
    </joint>
    <joint name="joint7">
      <param name="id">7</param>
      <command_interface name="position"/>
      <command_interface name="velocity"/>
      <state_interface name="position"/>
      <state_interface name="velocity"/>
      <state_interface name="effort"/>
    </joint>
  </ros2_control>
</robot>
